Workbook

Sheet Informations
B2: Informations
B3: Le but de ce fichier est de faciliter la gestion des salaires pour les clubs de La Lanterne Magique. Il est conçu pour une utilisation sur l'année civile et non sur l'exercice comptable des clubs, compte tenu que les déclarations aux caisses cantonales de compensation ainsi que l'établissement des certificats de salaires surviennent toujours au terme de l'année civile.
B5: Avertissement
B6: Les conditions suivantes doivent impérativement être remplies pour pouvoir utiliser ce fichier:
C7: 1. l'employeur engage exclusivement des collaborateurs·trices de nationalité suisse ou au bénéfice d'un permis de résidence (permis C); 2. le salaire d'aucun employé ne dépasse CHF 22'680.– par an.
B9: Avant de commencer
B10: Assurez-vous de remplir les conditions suivantes, consultez la documentation disponible sur Intranet et informez votre coordinateur·trice ASLM qui vous accompagnera dans vos démarches:
C11: – Le club dispose d'une assurance accident pour ses collaborateurs·trices
C12: – Le club s'est annoncé auprès de la caisse de compensation AVS compétente pour son canton
C13: – Le club a reçu de sa caisse de compensation AVS le détail des taux de cotisation en vigueur
B15: Comment utiliser ce fichier
B16: Ce fichier est composé de 7 onglets auxquels le club aura recours à différentes périodes de l'année. Les cellules à compléter sont indiquées en jaune dans chaque onglet.
B17: En début d'année
C18: 1. Configuration | D18: Renseigner les différents paramètres spécifiques à l'employeur
B19: En cours d'année
C20: 2. Collaborateurs·trices | D20: Saisir les coordonnées des collaborateurs·trices
C21: 3. Prestations | D21: Sélectionner les collaborateurs·trices et leur fonction lors des séances
C22: 4. Fiches de salaire | D22: Générer les fiches de salaire des collaborateurs·trices
B23: En fin d'année
C24: 5. Déclaration AVS | D24: Afficher les données utiles pour la déclaration annuelle des salaires à la caisse AVS
C25: 6. Certificats de salaires | D25: Afficher les données utiles pour la production des certificats de salaire annuels.
B29: Pour éviter des erreurs de saisie, ce fichier est protégée en écriture. Seules les cellules en couleur peuvent être modifiées. Le mot de passe permettant de déverouiller le fichier est: lanterne
H32: V.20260101

Sheet 1. Configuration
B1: =IF(ISBLANK(B8),"",B8)
A2: 1. Configuration
A3: Renseigner les données spécifiques au club dans les cellules en couleur.
A5: Année civile concernée | B5: 2026
A7: Données du club
A8: Raison sociale | B8: La Lanterne Magique de Testville
A9: Adresse | B9: Lanterne Magique de Testville c/o Exemple, Rue de l'Essai 9,
A10: NPA, Localité | B10: 1000 Lausanne
A12: Rémunération | B12: Salarié | C12: Indépendant
A13: Savant·e | B13: 355 | C13: 373
A14: Naïf·ve | B14: 253 | C14: 266
A15: Artiste | B15: 304 | C15: 319
A16: Musicien·ne | B16: 445 | C16: 465
A23: ="Séances "&B5 | B23: Dates
A24: ="Séance 4"&", "&"Saison "&($B$5-1)&"-"&$B$5 | B24: 46039 | E24: =IF(COUNTIF(B25:C35,B24),"Erreur! Il ne peut y avoir deux séances à une même date.","")
A25: ="Séance 5"&", "&"Saison "&($B$5-1)&"-"&$B$5 | B25: 46060 | E25: =IF(COUNTIF(B$24:C24,B25),"Erreur! Il ne peut y avoir deux séances à une même date.","")
A26: ="Séance 6"&", "&"Saison "&($B$5-1)&"-"&$B$5 | B26: 46088 | E26: =IF(COUNTIF(B$24:C25,B26),"Erreur! Il ne peut y avoir deux séances à une même date.","")
A27: ="Séance 7"&", "&"Saison "&($B$5-1)&"-"&$B$5 | B27: 46109 | E27: =IF(COUNTIF(B$24:C26,B27),"Erreur! Il ne peut y avoir deux séances à une même date.","")
A28: ="Séance 8"&", "&"Saison "&($B$5-1)&"-"&$B$5 | B28: 46137 | E28: =IF(COUNTIF(B$24:C27,B28),"Erreur! Il ne peut y avoir deux séances à une même date.","")
A29: ="Séance 9"&", "&"Saison "&($B$5-1)&"-"&$B$5 | B29: 46186 | E29: =IF(COUNTIF(B$24:C28,B29),"Erreur! Il ne peut y avoir deux séances à une même date.","")
A30: ="Séance 1"&", "&"Saison "&($B$5)&"-"&($B$5+1) | E30: =IF(COUNTIF(B$24:C29,B30),"Erreur! Il ne peut y avoir deux séances à une même date.","")
A31: ="Séance 2"&", "&"Saison "&($B$5)&"-"&($B$5+1) | E31: =IF(COUNTIF(B$24:C30,B31),"Erreur! Il ne peut y avoir deux séances à une même date.","")
A32: ="Séance 3"&", "&"Saison "&($B$5)&"-"&($B$5+1) | E32: =IF(COUNTIF(B$24:C31,B32),"Erreur! Il ne peut y avoir deux séances à une même date.","")
A33: Séance supplémentaire (si besoin) | E33: =IF(COUNTIF(B$24:C32,B33),"Erreur! Il ne peut y avoir deux séances à une même date.","")
A34: Séance supplémentaire (si besoin) | E34: =IF(COUNTIF(B$24:C33,B34),"Erreur! Il ne peut y avoir deux séances à une même date.","")
A35: Séance supplémentaire (si besoin) | E35: =IF(COUNTIF(B$24:C34,B35),"Erreur! Il ne peut y avoir deux séances à une même date.","")
A37: Indemnités, cotisation et autres frais | B37: Taux employé | C37: Taux employeur
A38: Indemnités vacances | B38: 0.1064
A39: Cotisations AVS/AI/APG | B39: 0.053 | C39: =B39
A40: Cotisations AC | B40: 0.011 | C40: =B40
A41: Cotisations AANP | B41: 0 | C41: =B41
A42: Cotisations APG-maladie | B42: 0 | C42: =B42
A43: Cotisations AFC | B43: 0 | C43: 0
A44: Autres déductions 1 (si besoin) | B44: 0 | C44: 0
A45: Autres déductions 2 (si besoin) | B45: 0 | C45: 0
A46: Total cotisations | B46: =SUM(B39:B45) | C46: =SUM(C39:C45)
A47: Frais d'administration | C47: 0.05
A48: Prime d'assurance accident (LAA) | C48: 100
A49: Accéder au site Internet de la caisse AVS compétente pour le détail des taux de cotisation.
A51: Franchise AVS | B51: non | C51: oui

Sheet 2. Collaborateurs·trices
L1: =IF(ISBLANK('1. Configuration'!B8),"",'1. Configuration'!B8)
A2: 2. Collaborateurs·trices
A3: Saisir les coordonnées des collaborateurs·trices du club dans les cellules en couleur. Celles des artistes placé·es par l'ASLM sont publiées dans le Registre des artistes.
A5: Prénom | B5: Nom | C5: Collaborateur·trice | D5: Adresse | E5: NPA, Localité | F5: E-mail | G5: Téléphone | H5: Statut | I5: Taux LPP | J5: Déclaration AVS | K5: Date naiss. | L5: N° AVS | M5: IBAN
A6: Camille | B6: Exemple | C6: =IF(A6>0,(A6&" "&B6),"") | D6: Rue Fictive 1 | E6: 1000 Lausanne | F6: camille@example.org | G6: 021 000 00 01 | H6: Salarié | I6: 0 | J6: oui | K6: 32875 | L6: 756.0000.0000.02 | M6: CH93 0076 2011 6238 5295 7
A7: Alex | B7: Martin | C7: =IF(A7>0,(A7&" "&B7),"") | D7: Chemin du Test 2 | E7: 1950 Sion | F7: alex@example.org | G7: 079 000 00 02 | H7: Salarié | I7: 0 | J7: oui | K7: 31173 | L7: 756.1111.1111.13 | M7: CH56 0483 5012 3456 7800 9
A8: Alex | B8: Martin | C8: =IF(A8>0,(A8&" "&B8),"") | D8: Avenue Modèle 3 | E8: 1200 Genève | F8: alex.m@example.org | G8: 079 000 00 03 | H8: Salarié | I8: 0 | J8: non | K8: 33667 | L8: 756.2222.2222.24 | M8: CH93 0076 2011 6238 5295 7
A9: Noa | B9: Indep | C9: =IF(A9>0,(A9&" "&B9),"") | D9: Place Imaginaire 4 | E9: 2000 Neuchâtel | F9: noa@example.org | G9: 078 000 00 04 | H9: Indépendant | I9: 0
C10: =IF(A10>0,(A10&" "&B10),"")
C11: =IF(A11>0,(A11&" "&B11),"")
C12: =IF(A12>0,(A12&" "&B12),"")
C13: =IF(A13>0,(A13&" "&B13),"")
C14: =IF(A14>0,(A14&" "&B14),"")
C15: =IF(A15>0,(A15&" "&B15),"")
C16: =IF(A16>0,(A16&" "&B16),"")
C17: =IF(A17>0,(A17&" "&B17),"")
C18: =IF(A18>0,(A18&" "&B18),"")
C19: =IF(A19>0,(A19&" "&B19),"")
C20: =IF(A20>0,(A20&" "&B20),"")
C21: =IF(A21>0,(A21&" "&B21),"")
... C40: =IF(A40>0,(A40&" "&B40),"")

Sheet 3. Prestations
N1: =IF(ISBLANK('1. Configuration'!B8),"",'1. Configuration'!B8)
D2: 3. Prestations
D3: Sélectionner les collaborateurs·trices intervenant dans le cadre de chacune des 9 séances du club et renseigner leur fonction.
D5: =TEXT(DAY('1. Configuration'!B24),"00")&"."&TEXT(MONTH('1. Configuration'!B24),"00")&"."&TEXT(YEAR('1. Configuration'!B24),"00")&" | "&'1. Configuration'!A24 | H5: Soumis à cotisation | L5: Non-soumis à cotisation
A6: Index Déclaration AVS | B6: Index cerficats de salaire | C6: ='1. Configuration'!B24 | D6: Collaborateur·trice | E6: Fonction | F6: Statut | G6: Déclaration AVS | H6: Salaire brut (incl. vac) | L6: Cachet | M6: Autre
A7: =IF(F7='1. Configuration'!$C$12,"",IF((G7='1. Configuration'!$C$51),(IF(D7>0,(IF(COUNTIF($D$6:D6,D7)>0,"",MAX($A$6:A6)+1)),"")),"")) | B7: {=IF((F7='1. Configuration'!$B$12),(IF(D7>0,(IF(COUNTIF($D$6:D6,D7)>0,"",MAX($B$6:B6)+1)),"")),"")} | C7: =D7&C$6 | D7: Camille Exemple | E7: Savant·e | F7: {=IFERROR(IF(INDEX('2. Collaborateurs·trices'!$A$6:$M$40,(MATCH('3. Prestations'!D7,'2. Collaborateurs·trices'!$C$6:$C$40,0)),8)=0,'1. Configuration'!$B$12,INDEX('2. Collaborateurs·trices'!$A$6:$M$40,(MATCH('3. Prestations'!D7,'2. Collaborateurs·trices'!$C$6:$C$40,0)),8)),'1. Configuration'!$B$12)} | G7: {=IFERROR(IF((INDEX('2. Collaborateurs·trices'!$A$6:$M$40,(MATCH('3. Prestations'!D7,'2. Collaborateurs·trices'!$C$6:$C$40,0)),10)=0),'1. Configuration'!$C$51,INDEX('2. Collaborateurs·trices'!$A$6:$M$40,(MATCH('3. Prestations'!D7,'2. Collaborateurs·trices'!$C$6:$C$40,0)),10)),IF(E7="","",'1. Configuration'!$C$51))} | H7: {=IFERROR(IF(AND(F7='1. Configuration'!$B$12,G7='1. Configuration'!$C$51),IF((F7='1. Configuration'!$B$12),(VLOOKUP(E7,'1. Configuration'!$A$13:$C$21,2,)),""),""),"")} | L7: {=IFERROR(IF((F7='1. Configuration'!$C$12),(VLOOKUP(E7,'1. Configuration'!$A$13:$C$21,3,)),(IF((G7='1. Configuration'!$B$51),(VLOOKUP(E7,'1. Configuration'!$A$13:$C$21,2,)),""))),"")}
A8: =IF(F8='1. Configuration'!$C$12,"",IF((G8='1. Configuration'!$C$51),(IF(D8>0,(IF(COUNTIF($D$6:D7,D8)>0,"",MAX($A$6:A7)+1)),"")),"")) | B8: =IF((F8='1. Configuration'!$B$12),(IF(D8>0,(IF(COUNTIF($D$6:D7,D8)>0,"",MAX($B$6:B7)+1)),"")),"") | C8: =D8&C$6 | D8: Noa Indep | E8: Artiste | F8: {=IFERROR(IF(INDEX('2. Collaborateurs·trices'!$A$6:$M$40,(MATCH('3. Prestations'!D8,'2. Collaborateurs·trices'!$C$6:$C$40,0)),8)=0,'1. Configuration'!$B$12,INDEX('2. Collaborateurs·trices'!$A$6:$M$40,(MATCH('3. Prestations'!D8,'2. Collaborateurs·trices'!$C$6:$C$40,0)),8)),'1. Configuration'!$B$12)} | G8: {=IFERROR(IF((INDEX('2. Collaborateurs·trices'!$A$6:$M$40,(MATCH('3. Prestations'!D8,'2. Collaborateurs·trices'!$C$6:$C$40,0)),10)=0),'1. Configuration'!$C$51,INDEX('2. Collaborateurs·trices'!$A$6:$M$40,(MATCH('3. Prestations'!D8,'2. Collaborateurs·trices'!$C$6:$C$40,0)),10)),IF(E8="","",'1. Configuration'!$C$51))} | H8: {=IFERROR(IF(AND(F8='1. Configuration'!$B$12,G8='1. Configuration'!$C$51),IF((F8='1. Configuration'!$B$12),(VLOOKUP(E8,'1. Configuration'!$A$13:$C$21,2,)),""),""),"")} | L8: {=IFERROR(IF((F8='1. Configuration'!$C$12),(VLOOKUP(E8,'1. Configuration'!$A$13:$C$21,3,)),(IF((G8='1. Configuration'!$B$51),(VLOOKUP(E8,'1. Configuration'!$A$13:$C$21,2,)),""))),"")}
A9: =IF(F9='1. Configuration'!$C$12,"",IF((G9='1. Configuration'!$C$51),(IF(D9>0,(IF(COUNTIF($D$6:D8,D9)>0,"",MAX($A$6:A8)+1)),"")),"")) | B9: {=IF((F9='1. Configuration'!$B$12),(IF(D9>0,(IF(COUNTIF($D$6:D8,D9)>0,"",MAX($B$6:B8)+1)),"")),"")} | C9: =D9&C$6 | F9: {=IFERROR(IF(INDEX('2. Collaborateurs·trices'!$A$6:$M$40,(MATCH('3. Prestations'!D9,'2. Collaborateurs·trices'!$C$6:$C$40,0)),8)=0,'1. Configuration'!$B$12,INDEX('2. Collaborateurs·trices'!$A$6:$M$40,(MATCH('3. Prestations'!D9,'2. Collaborateurs·trices'!$C$6:$C$40,0)),8)),'1. Configuration'!$B$12)} | G9: {=IFERROR(IF((INDEX('2. Collaborateurs·trices'!$A$6:$M$40,(MATCH('3. Prestations'!D9,'2. Collaborateurs·trices'!$C$6:$C$40,0)),10)=0),'1. Configuration'!$C$51,INDEX('2. Collaborateurs·trices'!$A$6:$M$40,(MATCH('3. Prestations'!D9,'2. Collaborateurs·trices'!$C$6:$C$40,0)),10)),IF(E9="","",'1. Configuration'!$C$51))} | H9: {=IFERROR(IF(AND(F9='1. Configuration'!$B$12,G9='1. Configuration'!$C$51),IF((F9='1. Configuration'!$B$12),(VLOOKUP(E9,'1. Configuration'!$A$13:$C$21,2,)),""),""),"")} | L9: {=IFERROR(IF((F9='1. Configuration'!$C$12),(VLOOKUP(E9,'1. Configuration'!$A$13:$C$21,3,)),(IF((G9='1. Configuration'!$B$51),(VLOOKUP(E9,'1. Configuration'!$A$13:$C$21,2,)),""))),"")}
A10: =IF(F10='1. Configuration'!$C$12,"",IF((G10='1. Configuration'!$C$51),(IF(D10>0,(IF(COUNTIF($D$6:D9,D10)>0,"",MAX($A$6:A9)+1)),"")),"")) | B10: {=IF((F10='1. Configuration'!$B$12),(IF(D10>0,(IF(COUNTIF($D$6:D9,D10)>0,"",MAX($B$6:B9)+1)),"")),"")} | C10: =D10&C$6 | F10: {=IFERROR(IF(INDEX('2. Collaborateurs·trices'!$A$6:$M$40,(MATCH('3. Prestations'!D10,'2. Collaborateurs·trices'!$C$6:$C$40,0)),8)=0,'1. Configuration'!$B$12,INDEX('2. Collaborateurs·trices'!$A$6:$M$40,(MATCH('3. Prestations'!D10,'2. Collaborateurs·trices'!$C$6:$C$40,0)),8)),"")} | G10: {=IFERROR(IF((INDEX('2. Collaborateurs·trices'!$A$6:$M$40,(MATCH('3. Prestations'!D10,'2. Collaborateurs·trices'!$C$6:$C$40,0)),10)=0),'1. Configuration'!$C$51,INDEX('2. Collaborateurs·trices'!$A$6:$M$40,(MATCH('3. Prestations'!D10,'2. Collaborateurs·trices'!$C$6:$C$40,0)),10)),IF(E10="","",'1. Configuration'!$C$51))} | H10: {=IFERROR(IF(AND(F10='1. Configuration'!$B$12,G10='1. Configuration'!$C$51),IF((F10='1. Configuration'!$B$12),(VLOOKUP(E10,'1. Configuration'!$A$13:$C$21,2,)),""),""),"")} | L10: {=IFERROR(IF((F10='1. Configuration'!$C$12),(VLOOKUP(E10,'1. Configuration'!$A$13:$C$21,3,)),(IF((G10='1. Configuration'!$B$51),(VLOOKUP(E10,'1. Configuration'!$A$13:$C$21,2,)),""))),"")}
A11: =IF(F11='1. Configuration'!$C$12,"",IF((G11='1. Configuration'!$C$51),(IF(D11>0,(IF(COUNTIF($D$6:D8,D11)>0,"",MAX($A$6:A8)+1)),"")),"")) | B11: {=IF((F11='1. Configuration'!$B$12),(IF(D11>0,(IF(COUNTIF($D$6:D10,D11)>0,"",MAX($B$6:B10)+1)),"")),"")} | C11: =D11&C$6 | F11: {=IFERROR(IF(INDEX('2. Collaborateurs·trices'!$A$6:$M$40,(MATCH('3. Prestations'!D11,'2. Collaborateurs·trices'!$C$6:$C$40,0)),8)=0,'1. Configuration'!$B$12,INDEX('2. Collaborateurs·trices'!$A$6:$M$40,(MATCH('3. Prestations'!D11,'2. Collaborateurs·trices'!$C$6:$C$40,0)),8)),"")} | G11: {=IFERROR(IF((INDEX('2. Collaborateurs·trices'!$A$6:$M$40,(MATCH('3. Prestations'!D11,'2. Collaborateurs·trices'!$C$6:$C$40,0)),10)=0),'1. Configuration'!$C$51,INDEX('2. Collaborateurs·trices'!$A$6:$M$40,(MATCH('3. Prestations'!D11,'2. Collaborateurs·trices'!$C$6:$C$40,0)),10)),IF(E11="","",'1. Configuration'!$C$51))} | H11: {=IFERROR(IF(AND(F11='1. Configuration'!$B$12,G11='1. Configuration'!$C$51),IF((F11='1. Configuration'!$B$12),(VLOOKUP(E11,'1. Configuration'!$A$13:$C$21,2,)),""),""),"")} | L11: {=IFERROR(IF((F11='1. Configuration'!$C$12),(VLOOKUP(E11,'1. Configuration'!$A$13:$C$21,3,)),(IF((G11='1. Configuration'!$B$51),(VLOOKUP(E11,'1. Configuration'!$A$13:$C$21,2,)),""))),"")}
A12: =IF(F12='1. Configuration'!$C$12,"",IF((G12='1. Configuration'!$C$51),(IF(D12>0,(IF(COUNTIF($D$6:D9,D12)>0,"",MAX($A$6:A9)+1)),"")),"")) | B12: {=IF((F12='1. Configuration'!$B$12),(IF(D12>0,(IF(COUNTIF($D$6:D11,D12)>0,"",MAX($B$6:B11)+1)),"")),"")} | C12: =D12&C$6 | F12: {=IFERROR(IF(INDEX('2. Collaborateurs·trices'!$A$6:$M$40,(MATCH('3. Prestations'!D12,'2. Collaborateurs·trices'!$C$6:$C$40,0)),8)=0,'1. Configuration'!$B$12,INDEX('2. Collaborateurs·trices'!$A$6:$M$40,(MATCH('3. Prestations'!D12,'2. Collaborateurs·trices'!$C$6:$C$40,0)),8)),"")} | G12: {=IFERROR(IF((INDEX('2. Collaborateurs·trices'!$A$6:$M$40,(MATCH('3. Prestations'!D12,'2. Collaborateurs·trices'!$C$6:$C$40,0)),10)=0),'1. Configuration'!$C$51,INDEX('2. Collaborateurs·trices'!$A$6:$M$40,(MATCH('3. Prestations'!D12,'2. Collaborateurs·trices'!$C$6:$C$40,0)),10)),IF(E12="","",'1. Configuration'!$C$51))} | H12: {=IFERROR(IF(AND(F12='1. Configuration'!$B$12,G12='1. Configuration'!$C$51),IF((F12='1. Configuration'!$B$12),(VLOOKUP(E12,'1. Configuration'!$A$13:$C$21,2,)),""),""),"")} | L12: {=IFERROR(IF((F12='1. Configuration'!$C$12),(VLOOKUP(E12,'1. Configuration'!$A$13:$C$21,3,)),(IF((G12='1. Configuration'!$B$51),(VLOOKUP(E12,'1. Configuration'!$A$13:$C$21,2,)),""))),"")}
A13: =IF(F13='1. Configuration'!$C$12,"",IF((G13='1. Configuration'!$C$51),(IF(D13>0,(IF(COUNTIF($D$6:D10,D13)>0,"",MAX($A$6:A10)+1)),"")),"")) | B13: {=IF((F13='1. Configuration'!$B$12),(IF(D13>0,(IF(COUNTIF($D$6:D12,D13)>0,"",MAX($B$6:B12)+1)),"")),"")} | C13: =D13&C$6 | F13: {=IFERROR(IF(INDEX('2. Collaborateurs·trices'!$A$6:$M$40,(MATCH('3. Prestations'!D13,'2. Collaborateurs·trices'!$C$6:$C$40,0)),8)=0,'1. Configuration'!$B$12,INDEX('2. Collaborateurs·trices'!$A$6:$M$40,(MATCH('3. Prestations'!D13,'2. Collaborateurs·trices'!$C$6:$C$40,0)),8)),"")} | G13: {=IFERROR(IF((INDEX('2. Collaborateurs·trices'!$A$6:$M$40,(MATCH('3. Prestations'!D13,'2. Collaborateurs·trices'!$C$6:$C$40,0)),10)=0),'1. Configuration'!$C$51,INDEX('2. Collaborateurs·trices'!$A$6:$M$40,(MATCH('3. Prestations'!D13,'2. Collaborateurs·trices'!$C$6:$C$40,0)),10)),IF(E13="","",'1. Configuration'!$C$51))} | H13: {=IFERROR(IF(AND(F13='1. Configuration'!$B$12,G13='1. Configuration'!$C$51),IF((F13='1. Configuration'!$B$12),(VLOOKUP(E13,'1. Configuration'!$A$13:$C$21,2,)),""),""),"")} | L13: {=IFERROR(IF((F13='1. Configuration'!$C$12),(VLOOKUP(E13,'1. Configuration'!$A$13:$C$21,3,)),(IF((G13='1. Configuration'!$B$51),(VLOOKUP(E13,'1. Configuration'!$A$13:$C$21,2,)),""))),"")}
A14: =IF(F14='1. Configuration'!$C$12,"",IF((G14='1. Configuration'!$C$51),(IF(D14>0,(IF(COUNTIF($D$6:D13,D14)>0,"",MAX($A$6:A13)+1)),"")),"")) | B14: {=IF((F14='1. Configuration'!$B$12),(IF(D14>0,(IF(COUNTIF($D$6:D13,D14)>0,"",MAX($B$6:B13)+1)),"")),"")} | C14: =D14&C$6 | F14: {=IFERROR(IF(INDEX('2. Collaborateurs·trices'!$A$6:$M$40,(MATCH('3. Prestations'!D14,'2. Collaborateurs·trices'!$C$6:$C$40,0)),8)=0,'1. Configuration'!$B$12,INDEX('2. Collaborateurs·trices'!$A$6:$M$40,(MATCH('3. Prestations'!D14,'2. Collaborateurs·trices'!$C$6:$C$40,0)),8)),"")} | G14: {=IFERROR(IF((INDEX('2. Collaborateurs·trices'!$A$6:$M$40,(MATCH('3. Prestations'!D14,'2. Collaborateurs·trices'!$C$6:$C$40,0)),10)=0),'1. Configuration'!$C$51,INDEX('2. Collaborateurs·trices'!$A$6:$M$40,(MATCH('3. Prestations'!D14,'2. Collaborateurs·trices'!$C$6:$C$40,0)),10)),IF(E14="","",'1. Configuration'!$C$51))} | H14: {=IFERROR(IF(AND(F14='1. Configuration'!$B$12,G14='1. Configuration'!$C$51),IF((F14='1. Configuration'!$B$12),(VLOOKUP(E14,'1. Configuration'!$A$13:$C$21,2,)),""),""),"")} | L14: {=IFERROR(IF((F14='1. Configuration'!$C$12),(VLOOKUP(E14,'1. Configuration'!$A$13:$C$21,3,)),(IF((G14='1. Configuration'!$B$51),(VLOOKUP(E14,'1. Configuration'!$A$13:$C$21,2,)),""))),"")}
A15: =IF(F15='1. Configuration'!$C$12,"",IF((G15='1. Configuration'!$C$51),(IF(D15>0,(IF(COUNTIF($D$6:D14,D15)>0,"",MAX($A$6:A14)+1)),"")),"")) | B15: {=IF((F15='1. Configuration'!$B$12),(IF(D15>0,(IF(COUNTIF($D$6:D14,D15)>0,"",MAX($B$6:B14)+1)),"")),"")}
A16: =IF(F16='1. Configuration'!$C$12,"",IF((G16='1. Configuration'!$C$51),(IF(D16>0,(IF(COUNTIF($D$6:D15,D16)>0,"",MAX($A$6:A15)+1)),"")),"")) | B16: {=IF((F16='1. Configuration'!$B$12),(IF(D16>0,(IF(COUNTIF($D$6:D15,D16)>0,"",MAX($B$6:B15)+1)),"")),"")} | D16: =TEXT(DAY('1. Configuration'!B25),"00")&"."&TEXT(MONTH('1. Configuration'!B25),"00")&"."&TEXT(YEAR('1. Configuration'!B25),"00")&" | "&'1. Configuration'!A25 | H16: =$H$5 | L16: =$L$5
A17: =IF(F17='1. Configuration'!$C$12,"",IF((G17='1. Configuration'!$C$51),(IF(D17>0,(IF(COUNTIF($D$6:D16,D17)>0,"",MAX($A$6:A16)+1)),"")),"")) | B17: {=IF((F17='1. Configuration'!$B$12),(IF(D17>0,(IF(COUNTIF($D$6:D16,D17)>0,"",MAX($B$6:B16)+1)),"")),"")} | C17: ='1. Configuration'!B25 | D17: =$D$6 | E17: =$E$6 | F17: =$F$6 | G17: =$G$6 | H17: =$H$6 | L17: =L$6 | M17: =$M$6
A18: =IF(F18='1. Configuration'!$C$12,"",IF((G18='1. Configuration'!$C$51),(IF(D18>0,(IF(COUNTIF($D$6:D17,D18)>0,"",MAX($A$6:A17)+1)),"")),"")) | B18: {=IF((F18='1. Configuration'!$B$12),(IF(D18>0,(IF(COUNTIF($D$6:D17,D18)>0,"",MAX($B$6:B17)+1)),"")),"")} | C18: =D18&C$17 | F18: {=IFERROR(IF(INDEX('2. Collaborateurs·trices'!$A$6:$M$40,(MATCH('3. Prestations'!D18,'2. Collaborateurs·trices'!$C$6:$C$40,0)),8)=0,'1. Configuration'!$B$12,INDEX('2. Collaborateurs·trices'!$A$6:$M$40,(MATCH('3. Prestations'!D18,'2. Collaborateurs·trices'!$C$6:$C$40,0)),8)),'1. Configuration'!$B$12)} | G18: {=IFERROR(IF((INDEX('2. Collaborateurs·trices'!$A$6:$M$40,(MATCH('3. Prestations'!D18,'2. Collaborateurs·trices'!$C$6:$C$40,0)),10)=0),'1. Configuration'!$C$51,INDEX('2. Collaborateurs·trices'!$A$6:$M$40,(MATCH('3. Prestations'!D18,'2. Collaborateurs·trices'!$C$6:$C$40,0)),10)),IF(E18="","",'1. Configuration'!$C$51))} | H18: {=IFERROR(IF(AND(F18='1. Configuration'!$B$12,G18='1. Configuration'!$C$51),IF((F18='1. Configuration'!$B$12),(VLOOKUP(E18,'1. Configuration'!$A$13:$C$21,2,)),""),""),"")} | L18: {=IFERROR(IF((F18='1. Configuration'!$C$12),(VLOOKUP(E18,'1. Configuration'!$A$13:$C$21,3,)),(IF((G18='1. Configuration'!$B$51),(VLOOKUP(E18,'1. Configuration'!$A$13:$C$21,2,)),""))),"")}
A19: =IF(F19='1. Configuration'!$C$12,"",IF((G19='1. Configuration'!$C$51),(IF(D19>0,(IF(COUNTIF($D$6:D18,D19)>0,"",MAX($A$6:A18)+1)),"")),"")) | B19: {=IF((F19='1. Configuration'!$B$12),(IF(D19>0,(IF(COUNTIF($D$6:D18,D19)>0,"",MAX($B$6:B18)+1)),"")),"")} | C19: =D19&C$17 | F19: {=IFERROR(IF(INDEX('2. Collaborateurs·trices'!$A$6:$M$40,(MATCH('3. Prestations'!D19,'2. Collaborateurs·trices'!$C$6:$C$40,0)),8)=0,'1. Configuration'!$B$12,INDEX('2. Collaborateurs·trices'!$A$6:$M$40,(MATCH('3. Prestations'!D19,'2. Collaborateurs·trices'!$C$6:$C$40,0)),8)),'1. Configuration'!$B$12)} | G19: {=IFERROR(IF((INDEX('2. Collaborateurs·trices'!$A$6:$M$40,(MATCH('3. Prestations'!D19,'2. Collaborateurs·trices'!$C$6:$C$40,0)),10)=0),'1. Configuration'!$C$51,INDEX('2. Collaborateurs·trices'!$A$6:$M$40,(MATCH('3. Prestations'!D19,'2. Collaborateurs·trices'!$C$6:$C$40,0)),10)),IF(E19="","",'1. Configuration'!$C$51))} | H19: {=IFERROR(IF(AND(F19='1. Configuration'!$B$12,G19='1. Configuration'!$C$51),IF((F19='1. Configuration'!$B$12),(VLOOKUP(E19,'1. Configuration'!$A$13:$C$21,2,)),""),""),"")} | L19: {=IFERROR(IF((F19='1. Configuration'!$C$12),(VLOOKUP(E19,'1. Configuration'!$A$13:$C$21,3,)),(IF((G19='1. Configuration'!$B$51),(VLOOKUP(E19,'1. Configuration'!$A$13:$C$21,2,)),""))),"")}
A20: =IF(F20='1. Configuration'!$C$12,"",IF((G20='1. Configuration'!$C$51),(IF(D20>0,(IF(COUNTIF($D$6:D19,D20)>0,"",MAX($A$6:A19)+1)),"")),"")) | B20: {=IF((F20='1. Configuration'!$B$12),(IF(D20>0,(IF(COUNTIF($D$6:D19,D20)>0,"",MAX($B$6:B19)+1)),"")),"")} | C20: =D20&C$17 | F20: {=IFERROR(IF(INDEX('2. Collaborateurs·trices'!$A$6:$M$40,(MATCH('3. Prestations'!D20,'2. Collaborateurs·trices'!$C$6:$C$40,0)),8)=0,'1. Configuration'!$B$12,INDEX('2. Collaborateurs·trices'!$A$6:$M$40,(MATCH('3. Prestations'!D20,'2. Collaborateurs·trices'!$C$6:$C$40,0)),8)),'1. Configuration'!$B$12)} | G20: {=IFERROR(IF((INDEX('2. Collaborateurs·trices'!$A$6:$M$40,(MATCH('3. Prestations'!D20,'2. Collaborateurs·trices'!$C$6:$C$40,0)),10)=0),'1. Configuration'!$C$51,INDEX('2. Collaborateurs·trices'!$A$6:$M$40,(MATCH('3. Prestations'!D20,'2. Collaborateurs·trices'!$C$6:$C$40,0)),10)),IF(E20="","",'1. Configuration'!$C$51))} | H20: {=IFERROR(IF(AND(F20='1. Configuration'!$B$12,G20='1. Configuration'!$C$51),IF((F20='1. Configuration'!$B$12),(VLOOKUP(E20,'1. Configuration'!$A$13:$C$21,2,)),""),""),"")} | L20: {=IFERROR(IF((F20='1. Configuration'!$C$12),(VLOOKUP(E20,'1. Configuration'!$A$13:$C$21,3,)),(IF((G20='1. Configuration'!$B$51),(VLOOKUP(E20,'1. Configuration'!$A$13:$C$21,2,)),""))),"")}
A21: =IF(F21='1. Configuration'!$C$12,"",IF((G21='1. Configuration'!$C$51),(IF(D21>0,(IF(COUNTIF($D$6:D20,D21)>0,"",MAX($A$6:A20)+1)),"")),"")) | B21: {=IF((F21='1. Configuration'!$B$12),(IF(D21>0,(IF(COUNTIF($D$6:D20,D21)>0,"",MAX($B$6:B20)+1)),"")),"")} | C21: =D21&C$17 | F21: {=IFERROR(IF(INDEX('2. Collaborateurs·trices'!$A$6:$M$40,(MATCH('3. Prestations'!D21,'2. Collaborateurs·trices'!$C$6:$C$40,0)),8)=0,'1. Configuration'!$B$12,INDEX('2. Collaborateurs·trices'!$A$6:$M$40,(MATCH('3. Prestations'!D21,'2. Collaborateurs·trices'!$C$6:$C$40,0)),8)),"")} | G21: {=IFERROR(IF((INDEX('2. Collaborateurs·trices'!$A$6:$M$40,(MATCH('3. Prestations'!D21,'2. Collaborateurs·trices'!$C$6:$C$40,0)),10)=0),'1. Configuration'!$C$51,INDEX('2. Collaborateurs·trices'!$A$6:$M$40,(MATCH('3. Prestations'!D21,'2. Collaborateurs·trices'!$C$6:$C$40,0)),10)),IF(E21="","",'1. Configuration'!$C$51))} | H21: {=IFERROR(IF(AND(F21='1. Configuration'!$B$12,G21='1. Configuration'!$C$51),IF((F21='1. Configuration'!$B$12),(VLOOKUP(E21,'1. Configuration'!$A$13:$C$21,2,)),""),""),"")} | L21: {=IFERROR(IF((F21='1. Configuration'!$C$12),(VLOOKUP(E21,'1. Configuration'!$A$13:$C$21,3,)),(IF((G21='1. Configuration'!$B$51),(VLOOKUP(E21,'1. Configuration'!$A$13:$C$21,2,)),""))),"")}
A22: =IF(F22='1. Configuration'!$C$12,"",IF((G22='1. Configuration'!$C$51),(IF(D22>0,(IF(COUNTIF($D$6:D21,D22)>0,"",MAX($A$6:A21)+1)),"")),"")) | B22: {=IF((F22='1. Configuration'!$B$12),(IF(D22>0,(IF(COUNTIF($D$6:D21,D22)>0,"",MAX($B$6:B21)+1)),"")),"")} | C22: =D22&C$17 | F22: {=IFERROR(IF(INDEX('2. Collaborateurs·trices'!$A$6:$M$40,(MATCH('3. Prestations'!D22,'2. Collaborateurs·trices'!$C$6:$C$40,0)),8)=0,'1. Configuration'!$B$12,INDEX('2. Collaborateurs·trices'!$A$6:$M$40,(MATCH('3. Prestations'!D22,'2. Collaborateurs·trices'!$C$6:$C$40,0)),8)),"")} | G22: {=IFERROR(IF((INDEX('2. Collaborateurs·trices'!$A$6:$M$40,(MATCH('3. Prestations'!D22,'2. Collaborateurs·trices'!$C$6:$C$40,0)),10)=0),'1. Configuration'!$C$51,INDEX('2. Collaborateurs·trices'!$A$6:$M$40,(MATCH('3. Prestations'!D22,'2. Collaborateurs·trices'!$C$6:$C$40,0)),10)),IF(E22="","",'1. Configuration'!$C$51))} | H22: {=IFERROR(IF(AND(F22='1. Configuration'!$B$12,G22='1. Configuration'!$C$51),IF((F22='1. Configuration'!$B$12),(VLOOKUP(E22,'1. Configuration'!$A$13:$C$21,2,)),""),""),"")} | L22: {=IFERROR(IF((F22='1. Configuration'!$C$12),(VLOOKUP(E22,'1. Configuration'!$A$13:$C$21,3,)),(IF((G22='1. Configuration'!$B$51),(VLOOKUP(E22,'1. Configuration'!$A$13:$C$21,2,)),""))),"")}
A23: =IF(F23='1. Configuration'!$C$12,"",IF((G23='1. Configuration'!$C$51),(IF(D23>0,(IF(COUNTIF($D$6:D22,D23)>0,"",MAX($A$6:A22)+1)),"")),"")) | B23: {=IF((F23='1. Configuration'!$B$12),(IF(D23>0,(IF(COUNTIF($D$6:D22,D23)>0,"",MAX($B$6:B22)+1)),"")),"")} | C23: =D23&C$17 | F23: {=IFERROR(IF(INDEX('2. Collaborateurs·trices'!$A$6:$M$40,(MATCH('3. Prestations'!D23,'2. Collaborateurs·trices'!$C$6:$C$40,0)),8)=0,'1. Configuration'!$B$12,INDEX('2. Collaborateurs·trices'!$A$6:$M$40,(MATCH('3. Prestations'!D23,'2. Collaborateurs·trices'!$C$6:$C$40,0)),8)),"")} | G23: {=IFERROR(IF((INDEX('2. Collaborateurs·trices'!$A$6:$M$40,(MATCH('3. Prestations'!D23,'2. Collaborateurs·trices'!$C$6:$C$40,0)),10)=0),'1. Configuration'!$C$51,INDEX('2. Collaborateurs·trices'!$A$6:$M$40,(MATCH('3. Prestations'!D23,'2. Collaborateurs·trices'!$C$6:$C$40,0)),10)),IF(E23="","",'1. Configuration'!$C$51))} | H23: {=IFERROR(IF(AND(F23='1. Configuration'!$B$12,G23='1. Configuration'!$C$51),IF((F23='1. Configuration'!$B$12),(VLOOKUP(E23,'1. Configuration'!$A$13:$C$21,2,)),""),""),"")} | L23: {=IFERROR(IF((F23='1. Configuration'!$C$12),(VLOOKUP(E23,'1. Configuration'!$A$13:$C$21,3,)),(IF((G23='1. Configuration'!$B$51),(VLOOKUP(E23,'1. Configuration'!$A$13:$C$21,2,)),""))),"")}
A24: =IF(F24='1. Configuration'!$C$12,"",IF((G24='1. Configuration'!$C$51),(IF(D24>0,(IF(COUNTIF($D$6:D23,D24)>0,"",MAX($A$6:A23)+1)),"")),"")) | B24: {=IF((F24='1. Configuration'!$B$12),(IF(D24>0,(IF(COUNTIF($D$6:D23,D24)>0,"",MAX($B$6:B23)+1)),"")),"")} | C24: =D24&C$17 | F24: {=IFERROR(IF(INDEX('2. Collaborateurs·trices'!$A$6:$M$40,(MATCH('3. Prestations'!D24,'2. Collaborateurs·trices'!$C$6:$C$40,0)),8)=0,'1. Configuration'!$B$12,INDEX('2. Collaborateurs·trices'!$A$6:$M$40,(MATCH('3. Prestations'!D24,'2. Collaborateurs·trices'!$C$6:$C$40,0)),8)),"")} | G24: {=IFERROR(IF((INDEX('2. Collaborateurs·trices'!$A$6:$M$40,(MATCH('3. Prestations'!D24,'2. Collaborateurs·trices'!$C$6:$C$40,0)),10)=0),'1. Configuration'!$C$51,INDEX('2. Collaborateurs·trices'!$A$6:$M$40,(MATCH('3. Prestations'!D24,'2. Collaborateurs·trices'!$C$6:$C$40,0)),10)),IF(E24="","",'1. Configuration'!$C$51))} | H24: {=IFERROR(IF(AND(F24='1. Configuration'!$B$12,G24='1. Configuration'!$C$51),IF((F24='1. Configuration'!$B$12),(VLOOKUP(E24,'1. Configuration'!$A$13:$C$21,2,)),""),""),"")} | L24: {=IFERROR(IF((F24='1. Configuration'!$C$12),(VLOOKUP(E24,'1. Configuration'!$A$13:$C$21,3,)),(IF((G24='1. Configuration'!$B$51),(VLOOKUP(E24,'1. Configuration'!$A$13:$C$21,2,)),""))),"")}
A25: =IF(F25='1. Configuration'!$C$12,"",IF((G25='1. Configuration'!$C$51),(IF(D25>0,(IF(COUNTIF($D$6:D24,D25)>0,"",MAX($A$6:A24)+1)),"")),"")) | B25: {=IF((F25='1. Configuration'!$B$12),(IF(D25>0,(IF(COUNTIF($D$6:D24,D25)>0,"",MAX($B$6:B24)+1)),"")),"")} | C25: =D25&C$17 | F25: {=IFERROR(IF(INDEX('2. Collaborateurs·trices'!$A$6:$M$40,(MATCH('3. Prestations'!D25,'2. Collaborateurs·trices'!$C$6:$C$40,0)),8)=0,'1. Configuration'!$B$12,INDEX('2. Collaborateurs·trices'!$A$6:$M$40,(MATCH('3. Prestations'!D25,'2. Collaborateurs·trices'!$C$6:$C$40,0)),8)),"")} | G25: {=IFERROR(IF((INDEX('2. Collaborateurs·trices'!$A$6:$M$40,(MATCH('3. Prestations'!D25,'2. Collaborateurs·trices'!$C$6:$C$40,0)),10)=0),'1. Configuration'!$C$51,INDEX('2. Collaborateurs·trices'!$A$6:$M$40,(MATCH('3. Prestations'!D25,'2. Collaborateurs·trices'!$C$6:$C$40,0)),10)),IF(E25="","",'1. Configuration'!$C$51))} | H25: {=IFERROR(IF(AND(F25='1. Configuration'!$B$12,G25='1. Configuration'!$C$51),IF((F25='1. Configuration'!$B$12),(VLOOKUP(E25,'1. Configuration'!$A$13:$C$21,2,)),""),""),"")} | L25: {=IFERROR(IF((F25='1. Configuration'!$C$12),(VLOOKUP(E25,'1. Configuration'!$A$13:$C$21,3,)),(IF((G25='1. Configuration'!$B$51),(VLOOKUP(E25,'1. Configuration'!$A$13:$C$21,2,)),""))),"")}
A26: =IF(F26='1. Configuration'!$C$12,"",IF((G26='1. Configuration'!$C$51),(IF(D26>0,(IF(COUNTIF($D$6:D25,D26)>0,"",MAX($A$6:A25)+1)),"")),"")) | B26: {=IF((F26='1. Configuration'!$B$12),(IF(D26>0,(IF(COUNTIF($D$6:D25,D26)>0,"",MAX($B$6:B25)+1)),"")),"")}
A27: =IF(F27='1. Configuration'!$C$12,"",IF((G27='1. Configuration'!$C$51),(IF(D27>0,(IF(COUNTIF($D$6:D26,D27)>0,"",MAX($A$6:A26)+1)),"")),"")) | B27: {=IF((F27='1. Configuration'!$B$12),(IF(D27>0,(IF(COUNTIF($D$6:D26,D27)>0,"",MAX($B$6:B26)+1)),"")),"")} | D27: =TEXT(DAY('1. Configuration'!B26),"00")&"."&TEXT(MONTH('1. Configuration'!B26),"00")&"."&TEXT(YEAR('1. Configuration'!B26),"00")&" | "&'1. Configuration'!A26 | H27: =$H$5 | L27: =$L$5
A28: =IF(F28='1. Configuration'!$C$12,"",IF((G28='1. Configuration'!$C$51),(IF(D28>0,(IF(COUNTIF($D$6:D27,D28)>0,"",MAX($A$6:A27)+1)),"")),"")) | B28: {=IF((F28='1. Configuration'!$B$12),(IF(D28>0,(IF(COUNTIF($D$6:D27,D28)>0,"",MAX($B$6:B27)+1)),"")),"")} | C28: ='1. Configuration'!B26 | D28: =$D$6 | E28: =$E$6 | F28: =$F$6 | G28: =$G$6 | H28: =$H$6 | L28: Cachet | M28: =$M$6
A29: =IF(F29='1. Configuration'!$C$12,"",IF((G29='1. Configuration'!$C$51),(IF(D29>0,(IF(COUNTIF($D$6:D28,D29)>0,"",MAX($A$6:A28)+1)),"")),"")) | B29: {=IF((F29='1. Configuration'!$B$12),(IF(D29>0,(IF(COUNTIF($D$6:D28,D29)>0,"",MAX($B$6:B28)+1)),"")),"")} | C29: =D29&C$28 | F29: {=IFERROR(IF(INDEX('2. Collaborateurs·trices'!$A$6:$M$40,(MATCH('3. Prestations'!D29,'2. Collaborateurs·trices'!$C$6:$C$40,0)),8)=0,'1. Configuration'!$B$12,INDEX('2. Collaborateurs·trices'!$A$6:$M$40,(MATCH('3. Prestations'!D29,'2. Collaborateurs·trices'!$C$6:$C$40,0)),8)),'1. Configuration'!$B$12)} | G29: {=IFERROR(IF((INDEX('2. Collaborateurs·trices'!$A$6:$M$40,(MATCH('3. Prestations'!D29,'2. Collaborateurs·trices'!$C$6:$C$40,0)),10)=0),'1. Configuration'!$C$51,INDEX('2. Collaborateurs·trices'!$A$6:$M$40,(MATCH('3. Prestations'!D29,'2. Collaborateurs·trices'!$C$6:$C$40,0)),10)),IF(E29="","",'1. Configuration'!$C$51))} | H29: {=IFERROR(IF(AND(F29='1. Configuration'!$B$12,G29='1. Configuration'!$C$51),IF((F29='1. Configuration'!$B$12),(VLOOKUP(E29,'1. Configuration'!$A$13:$C$21,2,)),""),""),"")} | L29: {=IFERROR(IF((F29='1. Configuration'!$C$12),(VLOOKUP(E29,'1. Configuration'!$A$13:$C$21,3,)),(IF((G29='1. Configuration'!$B$51),(VLOOKUP(E29,'1. Configuration'!$A$13:$C$21,2,)),""))),"")}
A30: =IF(F30='1. Configuration'!$C$12,"",IF((G30='1. Configuration'!$C$51),(IF(D30>0,(IF(COUNTIF($D$6:D29,D30)>0,"",MAX($A$6:A29)+1)),"")),"")) | B30: {=IF((F30='1. Configuration'!$B$12),(IF(D30>0,(IF(COUNTIF($D$6:D29,D30)>0,"",MAX($B$6:B29)+1)),"")),"")} | C30: =D30&C$28 | F30: {=IFERROR(IF(INDEX('2. Collaborateurs·trices'!$A$6:$M$40,(MATCH('3. Prestations'!D30,'2. Collaborateurs·trices'!$C$6:$C$40,0)),8)=0,'1. Configuration'!$B$12,INDEX('2. Collaborateurs·trices'!$A$6:$M$40,(MATCH('3. Prestations'!D30,'2. Collaborateurs·trices'!$C$6:$C$40,0)),8)),'1. Configuration'!$B$12)} | G30: {=IFERROR(IF((INDEX('2. Collaborateurs·trices'!$A$6:$M$40,(MATCH('3. Prestations'!D30,'2. Collaborateurs·trices'!$C$6:$C$40,0)),10)=0),'1. Configuration'!$C$51,INDEX('2. Collaborateurs·trices'!$A$6:$M$40,(MATCH('3. Prestations'!D30,'2. Collaborateurs·trices'!$C$6:$C$40,0)),10)),IF(E30="","",'1. Configuration'!$C$51))} | H30: {=IFERROR(IF(AND(F30='1. Configuration'!$B$12,G30='1. Configuration'!$C$51),IF((F30='1. Configuration'!$B$12),(VLOOKUP(E30,'1. Configuration'!$A$13:$C$21,2,)),""),""),"")} | L30: {=IFERROR(IF((F30='1. Configuration'!$C$12),(VLOOKUP(E30,'1. Configuration'!$A$13:$C$21,3,)),(IF((G30='1. Configuration'!$B$51),(VLOOKUP(E30,'1. Configuration'!$A$13:$C$21,2,)),""))),"")}
A31: =IF(F31='1. Configuration'!$C$12,"",IF((G31='1. Configuration'!$C$51),(IF(D31>0,(IF(COUNTIF($D$6:D30,D31)>0,"",MAX($A$6:A30)+1)),"")),"")) | B31: {=IF((F31='1. Configuration'!$B$12),(IF(D31>0,(IF(COUNTIF($D$6:D30,D31)>0,"",MAX($B$6:B30)+1)),"")),"")} | C31: =D31&C$28 | F31: {=IFERROR(IF(INDEX('2. Collaborateurs·trices'!$A$6:$M$40,(MATCH('3. Prestations'!D31,'2. Collaborateurs·trices'!$C$6:$C$40,0)),8)=0,'1. Configuration'!$B$12,INDEX('2. Collaborateurs·trices'!$A$6:$M$40,(MATCH('3. Prestations'!D31,'2. Collaborateurs·trices'!$C$6:$C$40,0)),8)),'1. Configuration'!$B$12)} | G31: {=IFERROR(IF((INDEX('2. Collaborateurs·trices'!$A$6:$M$40,(MATCH('3. Prestations'!D31,'2. Collaborateurs·trices'!$C$6:$C$40,0)),10)=0),'1. Configuration'!$C$51,INDEX('2. Collaborateurs·trices'!$A$6:$M$40,(MATCH('3. Prestations'!D31,'2. Collaborateurs·trices'!$C$6:$C$40,0)),10)),IF(E31="","",'1. Configuration'!$C$51))} | H31: {=IFERROR(IF(AND(F31='1. Configuration'!$B$12,G31='1. Configuration'!$C$51),IF((F31='1. Configuration'!$B$12),(VLOOKUP(E31,'1. Configuration'!$A$13:$C$21,2,)),""),""),"")} | L31: {=IFERROR(IF((F31='1. Configuration'!$C$12),(VLOOKUP(E31,'1. Configuration'!$A$13:$C$21,3,)),(IF((G31='1. Configuration'!$B$51),(VLOOKUP(E31,'1. Configuration'!$A$13:$C$21,2,)),""))),"")}
A32: =IF(F32='1. Configuration'!$C$12,"",IF((G32='1. Configuration'!$C$51),(IF(D32>0,(IF(COUNTIF($D$6:D31,D32)>0,"",MAX($A$6:A31)+1)),"")),"")) | B32: {=IF((F32='1. Configuration'!$B$12),(IF(D32>0,(IF(COUNTIF($D$6:D31,D32)>0,"",MAX($B$6:B31)+1)),"")),"")} | C32: =D32&C$28 | F32: {=IFERROR(IF(INDEX('2. Collaborateurs·trices'!$A$6:$M$40,(MATCH('3. Prestations'!D32,'2. Collaborateurs·trices'!$C$6:$C$40,0)),8)=0,'1. Configuration'!$B$12,INDEX('2. Collaborateurs·trices'!$A$6:$M$40,(MATCH('3. Prestations'!D32,'2. Collaborateurs·trices'!$C$6:$C$40,0)),8)),"")} | G32: {=IFERROR(IF((INDEX('2. Collaborateurs·trices'!$A$6:$M$40,(MATCH('3. Prestations'!D32,'2. Collaborateurs·trices'!$C$6:$C$40,0)),10)=0),'1. Configuration'!$C$51,INDEX('2. Collaborateurs·trices'!$A$6:$M$40,(MATCH('3. Prestations'!D32,'2. Collaborateurs·trices'!$C$6:$C$40,0)),10)),IF(E32="","",'1. Configuration'!$C$51))} | H32: {=IFERROR(IF(AND(F32='1. Configuration'!$B$12,G32='1. Configuration'!$C$51),IF((F32='1. Configuration'!$B$12),(VLOOKUP(E32,'1. Configuration'!$A$13:$C$21,2,)),""),""),"")} | L32: {=IFERROR(IF((F32='1. Configuration'!$C$12),(VLOOKUP(E32,'1. Configuration'!$A$13:$C$21,3,)),(IF((G32='1. Configuration'!$B$51),(VLOOKUP(E32,'1. Configuration'!$A$13:$C$21,2,)),""))),"")}
A33: =IF(F33='1. Configuration'!$C$12,"",IF((G33='1. Configuration'!$C$51),(IF(D33>0,(IF(COUNTIF($D$6:D32,D33)>0,"",MAX($A$6:A32)+1)),"")),"")) | B33: {=IF((F33='1. Configuration'!$B$12),(IF(D33>0,(IF(COUNTIF($D$6:D32,D33)>0,"",MAX($B$6:B32)+1)),"")),"")} | C33: =D33&C$28 | F33: {=IFERROR(IF(INDEX('2. Collaborateurs·trices'!$A$6:$M$40,(MATCH('3. Prestations'!D33,'2. Collaborateurs·trices'!$C$6:$C$40,0)),8)=0,'1. Configuration'!$B$12,INDEX('2. Collaborateurs·trices'!$A$6:$M$40,(MATCH('3. Prestations'!D33,'2. Collaborateurs·trices'!$C$6:$C$40,0)),8)),"")} | G33: {=IFERROR(IF((INDEX('2. Collaborateurs·trices'!$A$6:$M$40,(MATCH('3. Prestations'!D33,'2. Collaborateurs·trices'!$C$6:$C$40,0)),10)=0),'1. Configuration'!$C$51,INDEX('2. Collaborateurs·trices'!$A$6:$M$40,(MATCH('3. Prestations'!D33,'2. Collaborateurs·trices'!$C$6:$C$40,0)),10)),IF(E33="","",'1. Configuration'!$C$51))} | H33: {=IFERROR(IF(AND(F33='1. Configuration'!$B$12,G33='1. Configuration'!$C$51),IF((F33='1. Configuration'!$B$12),(VLOOKUP(E33,'1. Configuration'!$A$13:$C$21,2,)),""),""),"")} | L33: {=IFERROR(IF((F33='1. Configuration'!$C$12),(VLOOKUP(E33,'1. Configuration'!$A$13:$C$21,3,)),(IF((G33='1. Configuration'!$B$51),(VLOOKUP(E33,'1. Configuration'!$A$13:$C$21,2,)),""))),"")}
A34: =IF(F34='1. Configuration'!$C$12,"",IF((G34='1. Configuration'!$C$51),(IF(D34>0,(IF(COUNTIF($D$6:D33,D34)>0,"",MAX($A$6:A33)+1)),"")),"")) | B34: {=IF((F34='1. Configuration'!$B$12),(IF(D34>0,(IF(COUNTIF($D$6:D33,D34)>0,"",MAX($B$6:B33)+1)),"")),"")} | C34: =D34&C$28 | F34: {=IFERROR(IF(INDEX('2. Collaborateurs·trices'!$A$6:$M$40,(MATCH('3. Prestations'!D34,'2. Collaborateurs·trices'!$C$6:$C$40,0)),8)=0,'1. Configuration'!$B$12,INDEX('2. Collaborateurs·trices'!$A$6:$M$40,(MATCH('3. Prestations'!D34,'2. Collaborateurs·trices'!$C$6:$C$40,0)),8)),"")} | G34: {=IFERROR(IF((INDEX('2. Collaborateurs·trices'!$A$6:$M$40,(MATCH('3. Prestations'!D34,'2. Collaborateurs·trices'!$C$6:$C$40,0)),10)=0),'1. Configuration'!$C$51,INDEX('2. Collaborateurs·trices'!$A$6:$M$40,(MATCH('3. Prestations'!D34,'2. Collaborateurs·trices'!$C$6:$C$40,0)),10)),IF(E34="","",'1. Configuration'!$C$51))} | H34: {=IFERROR(IF(AND(F34='1. Configuration'!$B$12,G34='1. Configuration'!$C$51),IF((F34='1. Configuration'!$B$12),(VLOOKUP(E34,'1. Configuration'!$A$13:$C$21,2,)),""),""),"")} | L34: {=IFERROR(IF((F34='1. Configuration'!$C$12),(VLOOKUP(E34,'1. Configuration'!$A$13:$C$21,3,)),(IF((G34='1. Configuration'!$B$51),(VLOOKUP(E34,'1. Configuration'!$A$13:$C$21,2,)),""))),"")}
A35: =IF(F35='1. Configuration'!$C$12,"",IF((G35='1. Configuration'!$C$51),(IF(D35>0,(IF(COUNTIF($D$6:D34,D35)>0,"",MAX($A$6:A34)+1)),"")),"")) | B35: {=IF((F35='1. Configuration'!$B$12),(IF(D35>0,(IF(COUNTIF($D$6:D34,D35)>0,"",MAX($B$6:B34)+1)),"")),"")} | C35: =D35&C$28 | F35: {=IFERROR(IF(INDEX('2. Collaborateurs·trices'!$A$6:$M$40,(MATCH('3. Prestations'!D35,'2. Collaborateurs·trices'!$C$6:$C$40,0)),8)=0,'1. Configuration'!$B$12,INDEX('2. Collaborateurs·trices'!$A$6:$M$40,(MATCH('3. Prestations'!D35,'2. Collaborateurs·trices'!$C$6:$C$40,0)),8)),"")} | G35: {=IFERROR(IF((INDEX('2. Collaborateurs·trices'!$A$6:$M$40,(MATCH('3. Prestations'!D35,'2. Collaborateurs·trices'!$C$6:$C$40,0)),10)=0),'1. Configuration'!$C$51,INDEX('2. Collaborateurs·trices'!$A$6:$M$40,(MATCH('3. Prestations'!D35,'2. Collaborateurs·trices'!$C$6:$C$40,0)),10)),IF(E35="","",'1. Configuration'!$C$51))} | H35: {=IFERROR(IF(AND(F35='1. Configuration'!$B$12,G35='1. Configuration'!$C$51),IF((F35='1. Configuration'!$B$12),(VLOOKUP(E35,'1. Configuration'!$A$13:$C$21,2,)),""),""),"")} | L35: {=IFERROR(IF((F35='1. Configuration'!$C$12),(VLOOKUP(E35,'1. Configuration'!$A$13:$C$21,3,)),(IF((G35='1. Configuration'!$B$51),(VLOOKUP(E35,'1. Configuration'!$A$13:$C$21,2,)),""))),"")}
A36: =IF(F36='1. Configuration'!$C$12,"",IF((G36='1. Configuration'!$C$51),(IF(D36>0,(IF(COUNTIF($D$6:D35,D36)>0,"",MAX($A$6:A35)+1)),"")),"")) | B36: {=IF((F36='1. Configuration'!$B$12),(IF(D36>0,(IF(COUNTIF($D$6:D35,D36)>0,"",MAX($B$6:B35)+1)),"")),"")} | C36: =D36&C$28 | F36: {=IFERROR(IF(INDEX('2. Collaborateurs·trices'!$A$6:$M$40,(MATCH('3. Prestations'!D36,'2. Collaborateurs·trices'!$C$6:$C$40,0)),8)=0,'1. Configuration'!$B$12,INDEX('2. Collaborateurs·trices'!$A$6:$M$40,(MATCH('3. Prestations'!D36,'2. Collaborateurs·trices'!$C$6:$C$40,0)),8)),"")} | G36: {=IFERROR(IF((INDEX('2. Collaborateurs·trices'!$A$6:$M$40,(MATCH('3. Prestations'!D36,'2. Collaborateurs·trices'!$C$6:$C$40,0)),10)=0),'1. Configuration'!$C$51,INDEX('2. Collaborateurs·trices'!$A$6:$M$40,(MATCH('3. Prestations'!D36,'2. Collaborateurs·trices'!$C$6:$C$40,0)),10)),IF(E36="","",'1. Configuration'!$C$51))} | H36: {=IFERROR(IF(AND(F36='1. Configuration'!$B$12,G36='1. Configuration'!$C$51),IF((F36='1. Configuration'!$B$12),(VLOOKUP(E36,'1. Configuration'!$A$13:$C$21,2,)),""),""),"")} | L36: {=IFERROR(IF((F36='1. Configuration'!$C$12),(VLOOKUP(E36,'1. Configuration'!$A$13:$C$21,3,)),(IF((G36='1. Configuration'!$B$51),(VLOOKUP(E36,'1. Configuration'!$A$13:$C$21,2,)),""))),"")}
A37: =IF(F37='1. Configuration'!$C$12,"",IF((G37='1. Configuration'!$C$51),(IF(D37>0,(IF(COUNTIF($D$6:D36,D37)>0,"",MAX($A$6:A36)+1)),"")),"")) | B37: {=IF((F37='1. Configuration'!$B$12),(IF(D37>0,(IF(COUNTIF($D$6:D36,D37)>0,"",MAX($B$6:B36)+1)),"")),"")}
A38: =IF(F38='1. Configuration'!$C$12,"",IF((G38='1. Configuration'!$C$51),(IF(D38>0,(IF(COUNTIF($D$6:D37,D38)>0,"",MAX($A$6:A37)+1)),"")),"")) | B38: {=IF((F38='1. Configuration'!$B$12),(IF(D38>0,(IF(COUNTIF($D$6:D37,D38)>0,"",MAX($B$6:B37)+1)),"")),"")} | D38: =TEXT(DAY('1. Configuration'!B27),"00")&"."&TEXT(MONTH('1. Configuration'!B27),"00")&"."&TEXT(YEAR('1. Configuration'!B27),"00")&" | "&'1. Configuration'!A27 | H38: =$H$5 | L38: =$L$5
A39: =IF(F39='1. Configuration'!$C$12,"",IF((G39='1. Configuration'!$C$51),(IF(D39>0,(IF(COUNTIF($D$6:D38,D39)>0,"",MAX($A$6:A38)+1)),"")),"")) | B39: {=IF((F39='1. Configuration'!$B$12),(IF(D39>0,(IF(COUNTIF($D$6:D38,D39)>0,"",MAX($B$6:B38)+1)),"")),"")} | C39: ='1. Configuration'!B27 | D39: =$D$6 | E39: =$E$6 | F39: =$F$6 | G39: =$G$6 | H39: =$H$6 | L39: Cachet | M39: =$M$6
A40: =IF(F40='1. Configuration'!$C$12,"",IF((G40='1. Configuration'!$C$51),(IF(D40>0,(IF(COUNTIF($D$6:D39,D40)>0,"",MAX($A$6:A39)+1)),"")),"")) | B40: {=IF((F40='1. Configuration'!$B$12),(IF(D40>0,(IF(COUNTIF($D$6:D39,D40)>0,"",MAX($B$6:B39)+1)),"")),"")} | C40: =D40&C$39 | F40: {=IFERROR(IF(INDEX('2. Collaborateurs·trices'!$A$6:$M$40,(MATCH('3. Prestations'!D40,'2. Collaborateurs·trices'!$C$6:$C$40,0)),8)=0,'1. Configuration'!$B$12,INDEX('2. Collaborateurs·trices'!$A$6:$M$40,(MATCH('3. Prestations'!D40,'2. Collaborateurs·trices'!$C$6:$C$40,0)),8)),'1. Configuration'!$B$12)} | G40: {=IFERROR(IF((INDEX('2. Collaborateurs·trices'!$A$6:$M$40,(MATCH('3. Prestations'!D40,'2. Collaborateurs·trices'!$C$6:$C$40,0)),10)=0),'1. Configuration'!$C$51,INDEX('2. Collaborateurs·trices'!$A$6:$M$40,(MATCH('3. Prestations'!D40,'2. Collaborateurs·trices'!$C$6:$C$40,0)),10)),IF(E40="","",'1. Configuration'!$C$51))} | H40: {=IFERROR(IF(AND(F40='1. Configuration'!$B$12,G40='1. Configuration'!$C$51),IF((F40='1. Configuration'!$B$12),(VLOOKUP(E40,'1. Configuration'!$A$13:$C$21,2,)),""),""),"")} | L40: {=IFERROR(IF((F40='1. Configuration'!$C$12),(VLOOKUP(E40,'1. Configuration'!$A$13:$C$21,3,)),(IF((G40='1. Configuration'!$B$51),(VLOOKUP(E40,'1. Configuration'!$A$13:$C$21,2,)),""))),"")}
A41: =IF(F41='1. Configuration'!$C$12,"",IF((G41='1. Configuration'!$C$51),(IF(D41>0,(IF(COUNTIF($D$6:D40,D41)>0,"",MAX($A$6:A40)+1)),"")),"")) | B41: {=IF((F41='1. Configuration'!$B$12),(IF(D41>0,(IF(COUNTIF($D$6:D40,D41)>0,"",MAX($B$6:B40)+1)),"")),"")} | C41: =D41&C$39 | F41: {=IFERROR(IF(INDEX('2. Collaborateurs·trices'!$A$6:$M$40,(MATCH('3. Prestations'!D41,'2. Collaborateurs·trices'!$C$6:$C$40,0)),8)=0,'1. Configuration'!$B$12,INDEX('2. Collaborateurs·trices'!$A$6:$M$40,(MATCH('3. Prestations'!D41,'2. Collaborateurs·trices'!$C$6:$C$40,0)),8)),'1. Configuration'!$B$12)} | G41: {=IFERROR(IF((INDEX('2. Collaborateurs·trices'!$A$6:$M$40,(MATCH('3. Prestations'!D41,'2. Collaborateurs·trices'!$C$6:$C$40,0)),10)=0),'1. Configuration'!$C$51,INDEX('2. Collaborateurs·trices'!$A$6:$M$40,(MATCH('3. Prestations'!D41,'2. Collaborateurs·trices'!$C$6:$C$40,0)),10)),IF(E41="","",'1. Configuration'!$C$51))} | H41: {=IFERROR(IF(AND(F41='1. Configuration'!$B$12,G41='1. Configuration'!$C$51),IF((F41='1. Configuration'!$B$12),(VLOOKUP(E41,'1. Configuration'!$A$13:$C$21,2,)),""),""),"")} | L41: {=IFERROR(IF((F41='1. Configuration'!$C$12),(VLOOKUP(E41,'1. Configuration'!$A$13:$C$21,3,)),(IF((G41='1. Configuration'!$B$51),(VLOOKUP(E41,'1. Configuration'!$A$13:$C$21,2,)),""))),"")}
...

Sheet 4. Fiches de salaire
E1: =IF(ISBLANK('1. Configuration'!B8),"",'1. Configuration'!B8)
B2: 4. Fiches de salaire
B3: Renseigner les cellules en couleur pour générer une fiche de salaire pouvant être imprimée.
B4: ='2. Collaborateurs·trices'!C5 | E4: Séance
B5: Camille Exemple | E5: 46039
D8: =IF(B5="","Sélectionner un collaborateur",IF(E5="","Sélectionner une séance",IF(OR(I16='1. Configuration'!C12),"Sélectionner un collaborateur salarié",IF(I17="","Vérifier que la case ''Déclaration AVS'' relative au collaborateur sélectionné est remplie dans l'onglet 2",IF(F25="","Aucune prestation effectuée par le collaborateur à la date sélectionnée","")))))
C11: =IF('1. Configuration'!B8>0,'1. Configuration'!B8,"")
C12: =IF('1. Configuration'!B9>0,'1. Configuration'!B9,"")
C13: =IF('1. Configuration'!B10>0,'1. Configuration'!B10,"") | E13: =IFERROR(INDEX('2. Collaborateurs·trices'!A6:M40, MATCH('4. Fiches de salaire'!B5,'2. Collaborateurs·trices'!C6:C40,0),3),"")
E14: {=IFERROR(INDEX('2. Collaborateurs·trices'!A6:M40, MATCH('4. Fiches de salaire'!B5,'2. Collaborateurs·trices'!C6:C40,0),4),"")}
E15: {=IFERROR(INDEX('2. Collaborateurs·trices'!A6:M40, MATCH('4. Fiches de salaire'!B5,'2. Collaborateurs·trices'!C6:C40,0),5),"")} | I15: =B5&E5
I16: {=IFERROR(INDEX('2. Collaborateurs·trices'!A6:M40, MATCH('4. Fiches de salaire'!B5,'2. Collaborateurs·trices'!C6:C40,0),8),"")}
C17: =IF(ISBLANK(INDEX('2. Collaborateurs·trices'!A6:M40, MATCH('4. Fiches de salaire'!B5,'2. Collaborateurs·trices'!C6:C40,0),12)),"",'2. Collaborateurs·trices'!L5&": "&(INDEX('2. Collaborateurs·trices'!A6:M40, MATCH('4. Fiches de salaire'!B5,'2. Collaborateurs·trices'!C6:C40,0),12))) | I17: {=IFERROR(INDEX('2. Collaborateurs·trices'!A6:M40, MATCH('4. Fiches de salaire'!B5,'2. Collaborateurs·trices'!C6:C40,0),10),0)}
C18: =IF(ISBLANK(INDEX('2. Collaborateurs·trices'!A6:M40, MATCH('4. Fiches de salaire'!B5,'2. Collaborateurs·trices'!C6:C40,0),11)),"",'2. Collaborateurs·trices'!K5&": "&TEXT(DAY(INDEX('2. Collaborateurs·trices'!A6:M40, MATCH('4. Fiches de salaire'!B5,'2. Collaborateurs·trices'!C6:C40,0),11)),"00")&"."&TEXT(MONTH(INDEX('2. Collaborateurs·trices'!A6:M40, MATCH('4. Fiches de salaire'!B5,'2. Collaborateurs·trices'!C6:C40,0),11)),"00")&"."&TEXT(YEAR(INDEX('2. Collaborateurs·trices'!A6:M40, MATCH('4. Fiches de salaire'!B5,'2. Collaborateurs·trices'!C6:C40,0),11)),"0000"))
C19: =IFERROR('3. Prestations'!E6&": "&INDEX('3. Prestations'!C5:M136,MATCH('4. Fiches de salaire'!I15,'3. Prestations'!C5:C136,0),3),"")
C21: ="Fiche de salaire: séance du "&IF(E5>0,TEXT(DAY(E5),"00")&"."&TEXT(MONTH(E5),"00")&"."&TEXT(YEAR(E5),"00"),"")
C23: Position | D23: Facteur | F23: Montant
C25: Salaire de base | F25: =IFERROR(SUM(IF(I17='1. Configuration'!$C$51,(INDEX('3. Prestations'!C5:M136,MATCH('4. Fiches de salaire'!I15,'3. Prestations'!C5:C136,0),6)),(INDEX('3. Prestations'!C5:M136,MATCH('4. Fiches de salaire'!I15,'3. Prestations'!C5:C136,0),10))),)/SUM(100%+D26),"")
C26: =IF('1. Configuration'!A38="","",'1. Configuration'!A38) | D26: ='1. Configuration'!B38 | F26: =IFERROR(SUM(F25)*(D26),"")
C27: Salaire brut | F27: =SUM(F25:F26)
C29: =IF('1. Configuration'!A39="","",'1. Configuration'!A39) | D29: =IF($I$17='1. Configuration'!$B$51,0,'1. Configuration'!B39) | F29: =F27*D29
C30: =IF('1. Configuration'!A40="","",'1. Configuration'!A40) | D30: =IF($I$17='1. Configuration'!$B$51,0,'1. Configuration'!B40) | F30: =F27*D30
C31: =IF('1. Configuration'!A41="","",'1. Configuration'!A41) | D31: =IF($I$17='1. Configuration'!$B$51,0,'1. Configuration'!B41) | F31: =F27*D31
C32: =IF('1. Configuration'!A42="","",'1. Configuration'!A42) | D32: =IF($I$17='1. Configuration'!$B$51,0,'1. Configuration'!B42) | F32: =F27*D32
C33: Cotisations LPP | D33: =IFERROR((INDEX('2. Collaborateurs·trices'!A6:M40,MATCH(B5,'2. Collaborateurs·trices'!C6:C40,0),9)),0) | F33: =F27*D33
C34: =IF('1. Configuration'!A43="","",'1. Configuration'!A43) | D34: =IF($I$17='1. Configuration'!$B$51,0,'1. Configuration'!B43) | F34: =F27*D34
C35: =IF('1. Configuration'!A44="","",'1. Configuration'!A44) | D35: =IF($I$17='1. Configuration'!$B$51,0,'1. Configuration'!B44) | F35: =F27*D35
C36: =IF('1. Configuration'!A45="","",'1. Configuration'!A45) | D36: =IF($I$17='1. Configuration'!$B$51,0,'1. Configuration'!B45) | F36: =F27*D36
C37: Total déductions | F37: =SUM(F29:F36)
C39: Salaire net | F39: =F27-F37
C41: ='3. Prestations'!M6 | F41: =IFERROR(INDEX('3. Prestations'!C5:M136,MATCH('4. Fiches de salaire'!I15,'3. Prestations'!C5:C136,0),11),"")
C42: Suppléments non-soumis à cotisations | F42: =SUM(F41:F41)
C44: {=IFERROR("Total versé sur le compte "&(INDEX('2. Collaborateurs·trices'!A6:M40,MATCH(B5,'2. Collaborateurs·trices'!C6:C40,0),13)),"")} | F44: =MROUND(SUM(F39+F42),0.05)
C46: Remarque:
F47: =TODAY()

Sheet 5. Déclaration AVS
D1: =IF(ISBLANK('1. Configuration'!B8),"",'1. Configuration'!B8)
A2: 5. Déclaration AVS
A3: Récapitulatif utile à l'établissement de la déclaration annuelle des salaires à la caisse cantonale de compensation AVS .
A5: ='2. Collaborateurs·trices'!L5 | B5: ='2. Collaborateurs·trices'!C5 | C5: ='2. Collaborateurs·trices'!K5 | D5: Salaire brut
A6: =IF(B6="","",(INDEX('2. Collaborateurs·trices'!$A$6:$M$40, MATCH('5. Déclaration AVS'!B6,'2. Collaborateurs·trices'!$C$6:$C$40,0),12))) | B6: =IFERROR(VLOOKUP(ROWS($B$6:B6),'3. Prestations'!$A$6:$D$136,4,FALSE),"") | C6: =IF(B6="","",(INDEX('2. Collaborateurs·trices'!$A$6:$M$40, MATCH('5. Déclaration AVS'!B6,'2. Collaborateurs·trices'!$C$6:$C$40,0),11))) | D6: =IF(B6="","",(SUMIFS('3. Prestations'!$H$7:$H$136,'3. Prestations'!$D$7:$D$136,'5. Déclaration AVS'!B6)))
A7: =IF(B7="","",(INDEX('2. Collaborateurs·trices'!$A$6:$M$40, MATCH('5. Déclaration AVS'!B7,'2. Collaborateurs·trices'!$C$6:$C$40,0),12))) | B7: =IFERROR(VLOOKUP(ROWS($B$6:B7),'3. Prestations'!$A$6:$D$136,4,FALSE),"") | C7: =IF(B7="","",(INDEX('2. Collaborateurs·trices'!$A$6:$M$40, MATCH('5. Déclaration AVS'!B7,'2. Collaborateurs·trices'!$C$6:$C$40,0),11))) | D7: =IF(B7="","",(SUMIFS('3. Prestations'!$H$7:$H$136,'3. Prestations'!$D$7:$D$136,'5. Déclaration AVS'!B7)))
A8: =IF(B8="","",(INDEX('2. Collaborateurs·trices'!$A$6:$M$40, MATCH('5. Déclaration AVS'!B8,'2. Collaborateurs·trices'!$C$6:$C$40,0),12))) | B8: =IFERROR(VLOOKUP(ROWS($B$6:B8),'3. Prestations'!$A$6:$D$136,4,FALSE),"") | C8: =IF(B8="","",(INDEX('2. Collaborateurs·trices'!$A$6:$M$40, MATCH('5. Déclaration AVS'!B8,'2. Collaborateurs·trices'!$C$6:$C$40,0),11))) | D8: =IF(B8="","",(SUMIFS('3. Prestations'!$H$7:$H$136,'3. Prestations'!$D$7:$D$136,'5. Déclaration AVS'!B8)))
A9: =IF(B9="","",(INDEX('2. Collaborateurs·trices'!$A$6:$M$40, MATCH('5. Déclaration AVS'!B9,'2. Collaborateurs·trices'!$C$6:$C$40,0),12))) | B9: =IFERROR(VLOOKUP(ROWS($B$6:B9),'3. Prestations'!$A$6:$D$136,4,FALSE),"") | C9: =IF(B9="","",(INDEX('2. Collaborateurs·trices'!$A$6:$M$40, MATCH('5. Déclaration AVS'!B9,'2. Collaborateurs·trices'!$C$6:$C$40,0),11))) | D9: =IF(B9="","",(SUMIFS('3. Prestations'!$H$7:$H$136,'3. Prestations'!$D$7:$D$136,'5. Déclaration AVS'!B9)))
A10: =IF(B10="","",(INDEX('2. Collaborateurs·trices'!$A$6:$M$40, MATCH('5. Déclaration AVS'!B10,'2. Collaborateurs·trices'!$C$6:$C$40,0),12))) | B10: =IFERROR(VLOOKUP(ROWS($B$6:B10),'3. Prestations'!$A$6:$D$136,4,FALSE),"") | C10: =IF(B10="","",(INDEX('2. Collaborateurs·trices'!$A$6:$M$40, MATCH('5. Déclaration AVS'!B10,'2. Collaborateurs·trices'!$C$6:$C$40,0),11))) | D10: =IF(B10="","",(SUMIFS('3. Prestations'!$H$7:$H$136,'3. Prestations'!$D$7:$D$136,'5. Déclaration AVS'!B10)))
A11: =IF(B11="","",(INDEX('2. Collaborateurs·trices'!$A$6:$M$40, MATCH('5. Déclaration AVS'!B11,'2. Collaborateurs·trices'!$C$6:$C$40,0),12))) | B11: =IFERROR(VLOOKUP(ROWS($B$6:B11),'3. Prestations'!$A$6:$D$136,4,FALSE),"") | C11: =IF(B11="","",(INDEX('2. Collaborateurs·trices'!$A$6:$M$40, MATCH('5. Déclaration AVS'!B11,'2. Collaborateurs·trices'!$C$6:$C$40,0),11))) | D11: =IF(B11="","",(SUMIFS('3. Prestations'!$H$7:$H$136,'3. Prestations'!$D$7:$D$136,'5. Déclaration AVS'!B11)))
A12: =IF(B12="","",(INDEX('2. Collaborateurs·trices'!$A$6:$M$40, MATCH('5. Déclaration AVS'!B12,'2. Collaborateurs·trices'!$C$6:$C$40,0),12))) | B12: =IFERROR(VLOOKUP(ROWS($B$6:B12),'3. Prestations'!$A$6:$D$136,4,FALSE),"") | C12: =IF(B12="","",(INDEX('2. Collaborateurs·trices'!$A$6:$M$40, MATCH('5. Déclaration AVS'!B12,'2. Collaborateurs·trices'!$C$6:$C$40,0),11))) | D12: =IF(B12="","",(SUMIFS('3. Prestations'!$H$7:$H$136,'3. Prestations'!$D$7:$D$136,'5. Déclaration AVS'!B12)))
A13: =IF(B13="","",(INDEX('2. Collaborateurs·trices'!$A$6:$M$40, MATCH('5. Déclaration AVS'!B13,'2. Collaborateurs·trices'!$C$6:$C$40,0),12))) | B13: =IFERROR(VLOOKUP(ROWS($B$6:B13),'3. Prestations'!$A$6:$D$136,4,FALSE),"") | C13: =IF(B13="","",(INDEX('2. Collaborateurs·trices'!$A$6:$M$40, MATCH('5. Déclaration AVS'!B13,'2. Collaborateurs·trices'!$C$6:$C$40,0),11))) | D13: =IF(B13="","",(SUMIFS('3. Prestations'!$H$7:$H$136,'3. Prestations'!$D$7:$D$136,'5. Déclaration AVS'!B13)))
A14: =IF(B14="","",(INDEX('2. Collaborateurs·trices'!$A$6:$M$40, MATCH('5. Déclaration AVS'!B14,'2. Collaborateurs·trices'!$C$6:$C$40,0),12))) | B14: =IFERROR(VLOOKUP(ROWS($B$6:B14),'3. Prestations'!$A$6:$D$136,4,FALSE),"") | C14: =IF(B14="","",(INDEX('2. Collaborateurs·trices'!$A$6:$M$40, MATCH('5. Déclaration AVS'!B14,'2. Collaborateurs·trices'!$C$6:$C$40,0),11))) | D14: =IF(B14="","",(SUMIFS('3. Prestations'!$H$7:$H$136,'3. Prestations'!$D$7:$D$136,'5. Déclaration AVS'!B14)))
A15: =IF(B15="","",(INDEX('2. Collaborateurs·trices'!$A$6:$M$40, MATCH('5. Déclaration AVS'!B15,'2. Collaborateurs·trices'!$C$6:$C$40,0),12))) | B15: =IFERROR(VLOOKUP(ROWS($B$6:B15),'3. Prestations'!$A$6:$D$136,4,FALSE),"") | C15: =IF(B15="","",(INDEX('2. Collaborateurs·trices'!$A$6:$M$40, MATCH('5. Déclaration AVS'!B15,'2. Collaborateurs·trices'!$C$6:$C$40,0),11))) | D15: =IF(B15="","",(SUMIFS('3. Prestations'!$H$7:$H$136,'3. Prestations'!$D$7:$D$136,'5. Déclaration AVS'!B15)))
A16: =IF(B16="","",(INDEX('2. Collaborateurs·trices'!$A$6:$M$40, MATCH('5. Déclaration AVS'!B16,'2. Collaborateurs·trices'!$C$6:$C$40,0),12))) | B16: =IFERROR(VLOOKUP(ROWS($B$6:B16),'3. Prestations'!$A$6:$D$136,4,FALSE),"") | C16: =IF(B16="","",(INDEX('2. Collaborateurs·trices'!$A$6:$M$40, MATCH('5. Déclaration AVS'!B16,'2. Collaborateurs·trices'!$C$6:$C$40,0),11))) | D16: =IF(B16="","",(SUMIFS('3. Prestations'!$H$7:$H$136,'3. Prestations'!$D$7:$D$136,'5. Déclaration AVS'!B16)))
A17: =IF(B17="","",(INDEX('2. Collaborateurs·trices'!$A$6:$M$40, MATCH('5. Déclaration AVS'!B17,'2. Collaborateurs·trices'!$C$6:$C$40,0),12))) | B17: =IFERROR(VLOOKUP(ROWS($B$6:B17),'3. Prestations'!$A$6:$D$136,4,FALSE),"") | C17: =IF(B17="","",(INDEX('2. Collaborateurs·trices'!$A$6:$M$40, MATCH('5. Déclaration AVS'!B17,'2. Collaborateurs·trices'!$C$6:$C$40,0),11))) | D17: =IF(B17="","",(SUMIFS('3. Prestations'!$H$7:$H$136,'3. Prestations'!$D$7:$D$136,'5. Déclaration AVS'!B17)))
... A40: =IF(B40="","",(INDEX('2. Collaborateurs·trices'!$A$6:$M$40, MATCH('5. Déclaration AVS'!B40,'2. Collaborateurs·trices'!$C$6:$C$40,0),12))) | B40: =IFERROR(VLOOKUP(ROWS($B$6:B40),'3. Prestations'!$A$6:$D$136,4,FALSE),"") | C40: =IF(B40="","",(INDEX('2. Collaborateurs·trices'!$A$6:$M$40, MATCH('5. Déclaration AVS'!B40,'2. Collaborateurs·trices'!$C$6:$C$40,0),11))) | D40: =IF(B40="","",(SUMIFS('3. Prestations'!$H$7:$H$136,'3. Prestations'!$D$7:$D$136,'5. Déclaration AVS'!B40)))
A41: ="Total "&('1. Configuration'!B5) | D41: =SUM(D6:D40)

Sheet 6. Certificats de salaire
I1: =IF(ISBLANK('1. Configuration'!B8),"",'1. Configuration'!B8)
A2: 6. Certificats de salaire
A3: Récapitulatif des données utiles à l'établissement des certificats de salaires
A5: ="Nouveau "&'2. Collaborateurs·trices'!L5 | B5: Date naiss. | C5: ='2. Collaborateurs·trices'!C5 | D5: Adresse | E5: Déclaration AVS | F5: Taux LPP | G5: Salaire brut | H5: AVS/AI/AC | I5: LPP | J5: Salaire net | K5: Autres
A6: Lettre C | B6: Lettre C | C6: Lettre H | D6: Lettre H | G6: Chiffres 1 et 8 | H6: Chiffre 9 | I6: Chiffre 10.1 | J6: Chiffre 11 | K6: Chiffre 13.1
A7: =IF(C7="","",(INDEX('2. Collaborateurs·trices'!$A$6:$M$40, MATCH(C7,'2. Collaborateurs·trices'!$C$6:$C$40,0),12))) | B7: =IF(C7="","",(INDEX('2. Collaborateurs·trices'!$A$6:$M$40, MATCH(C7,'2. Collaborateurs·trices'!$C$6:$C$40,0),11))) | C7: =IFERROR(VLOOKUP(ROWS($C$7:C7),'3. Prestations'!$B$6:$D$136,3,FALSE),"") | D7: =IF(C7="","",(INDEX('2. Collaborateurs·trices'!$A$6:$M$40, MATCH(C7,'2. Collaborateurs·trices'!$C$6:$C$40,0),4))&" "&(INDEX('2. Collaborateurs·trices'!$A$6:$M$40, MATCH(C7,'2. Collaborateurs·trices'!$C$6:$C$40,0),5))) | E7: {=IF(C7="","",(INDEX('2. Collaborateurs·trices'!$A$6:$M$40, MATCH(C7,'2. Collaborateurs·trices'!$C$6:$C$40,0),10)))} | F7: {=IF(C7="","",(INDEX('2. Collaborateurs·trices'!$A$6:$M$40, MATCH(C7,'2. Collaborateurs·trices'!$C$6:$C$40,0),9)))} | G7: =IF(C7="","",TRUNC(SUM((SUMIFS('3. Prestations'!$H$7:$H$136,'3. Prestations'!$D$7:$D$136,C7)),(SUMIFS('3. Prestations'!$L$7:$L$136,'3. Prestations'!$D$7:$D$136,C7))))) | H7: =IFERROR(IF(E7='1. Configuration'!$C$51,(TRUNC(SUM(G7*(SUM('1. Configuration'!B$39,'1. Configuration'!B$40))))),""),"") | I7: =IFERROR(TRUNC(G7*F7),"") | J7: =IFERROR(SUM(G7-H7-I7),"") | K7: =IF(C7="","",(SUMIFS('3. Prestations'!$M$7:$M$136,'3. Prestations'!$D$7:$D$136,'5. Déclaration AVS'!B6)))
A8: {=IF(C8="","",(INDEX('2. Collaborateurs·trices'!$A$6:$M$40, MATCH(C8,'2. Collaborateurs·trices'!$C$6:$C$40,0),12)))} | B8: =IF(C8="","",(INDEX('2. Collaborateurs·trices'!$A$6:$M$40, MATCH(C8,'2. Collaborateurs·trices'!$C$6:$C$40,0),11))) | C8: =IFERROR(VLOOKUP(ROWS($C$7:C8),'3. Prestations'!$B$6:$D$136,3,FALSE),"") | D8: {=IF(C8="","",(INDEX('2. Collaborateurs·trices'!$A$6:$M$40, MATCH(C8,'2. Collaborateurs·trices'!$C$6:$C$40,0),4))&" "&(INDEX('2. Collaborateurs·trices'!$A$6:$M$40, MATCH(C8,'2. Collaborateurs·trices'!$C$6:$C$40,0),5)))} | E8: {=IF(C8="","",(INDEX('2. Collaborateurs·trices'!$A$6:$M$40, MATCH(C8,'2. Collaborateurs·trices'!$C$6:$C$40,0),10)))} | F8: {=IF(C8="","",(INDEX('2. Collaborateurs·trices'!$A$6:$M$40, MATCH(C8,'2. Collaborateurs·trices'!$C$6:$C$40,0),9)))} | G8: =IF(C8="","",TRUNC(SUM((SUMIFS('3. Prestations'!$H$7:$H$136,'3. Prestations'!$D$7:$D$136,C8)),(SUMIFS('3. Prestations'!$L$7:$L$136,'3. Prestations'!$D$7:$D$136,C8))))) | H8: =IFERROR(IF(E8='1. Configuration'!$C$51,(TRUNC(SUM(G8*(SUM('1. Configuration'!B$39,'1. Configuration'!B$40))))),""),"") | I8: =IFERROR(TRUNC(G8*F8),"") | J8: =IFERROR(SUM(G8-H8-I8),"") | K8: =IF(C8="","",(SUMIFS('3. Prestations'!$M$7:$M$136,'3. Prestations'!$D$7:$D$136,'5. Déclaration AVS'!B7)))
